<?xml version="1.0"?>
<robot name="look_twice_diff_drive_scout">
  <link name="base_link">
    <visual>
      <geometry><box size="0.36 0.28 0.16"/></geometry>
      <material name="blue"><color rgba="0.2 0.4 0.85 1"/></material>
    </visual>
    <collision>
      <geometry><box size="0.36 0.28 0.16"/></geometry>
    </collision>
    <inertial>
      <mass value="8.0"/>
      <inertia ixx="0.12" ixy="0" ixz="0" iyy="0.15" iyz="0" izz="0.18"/>
    </inertial>
  </link>
  <link name="left_wheel">
    <visual><geometry><cylinder radius="0.06" length="0.04"/></geometry></visual>
    <collision><geometry><cylinder radius="0.06" length="0.04"/></geometry></collision>
    <inertial>
      <mass value="0.4"/>
      <inertia ixx="0.001" ixy="0" ixz="0" iyy="0.001" iyz="0" izz="0.001"/>
    </inertial>
  </link>
  <link name="right_wheel">
    <visual><geometry><cylinder radius="0.06" length="0.04"/></geometry></visual>
    <collision><geometry><cylinder radius="0.06" length="0.04"/></geometry></collision>
    <inertial>
      <mass value="0.4"/>
      <inertia ixx="0.001" ixy="0" ixz="0" iyy="0.001" iyz="0" izz="0.001"/>
    </inertial>
  </link>
  <link name="caster">
    <visual><geometry><sphere radius="0.03"/></geometry></visual>
    <collision><geometry><sphere radius="0.03"/></geometry></collision>
    <inertial>
      <mass value="0.1"/>
      <inertia ixx="0.0001" ixy="0" ixz="0" iyy="0.0001" iyz="0" izz="0.0001"/>
    </inertial>
  </link>
  <joint name="left_wheel_joint" type="continuous">
    <parent link="base_link"/>
    <child link="left_wheel"/>
    <origin xyz="0 0.16 -0.05" rpy="1.5708 0 0"/>
    <axis xyz="0 0 1"/>
  </joint>
  <joint name="right_wheel_joint" type="continuous">
    <parent link="base_link"/>
    <child link="right_wheel"/>
    <origin xyz="0 -0.16 -0.05" rpy="1.5708 0 0"/>
    <axis xyz="0 0 1"/>
  </joint>
  <joint name="caster_joint" type="fixed">
    <parent link="base_link"/>
    <child link="caster"/>
    <origin xyz="-0.12 0 -0.08" rpy="0 0 0"/>
  </joint>
</robot>
